Workbook
Name Slicer_Diabetes_Status1: #N/A
Name Slicer_Weight_Status1: #N/A

Sheet Customer Names
A1: Customer ID | B1: name
A2: Id1 | B2: Hawks, Ms. Kelly
A3: Id2 | B3: Lehner, Mr. Matthew D
A4: Id3 | B4: Lu, Mr. Phil
A5: Id4 | B5: Osborne, Ms. Kelsey
A6: Id5 | B6: Kadala, Ms. Kristyn
A7: Id6 | B7: Baker, Mr. Russell B.
A8: Id7 | B8: Macpherson, Mr. Scott
A9: Id8 | B9: Hallman, Mr. Stephen
A10: Id9 | B10: Moran, Mr. Patrick R.
A11: Id10 | B11: Benner, Ms. Brooke N.
A12: Id11 | B12: Fierro Vargas, Ms. Paola Andrea
... A2336: Id2335 | B2336: German, Mr. Aaron K

Sheet Medical Examinations
A1: Customer ID | B1: BMI | C1: HBA1C | D1: Heart Issues | E1: Any Transplants | F1: Cancer history | G1: NumberOfMajorSurgeries | H1: smoker
A2: Id1 | B2: 47.41 | C2: 7.47 | D2: No | E2: No | F2: No | G2: No major surgery | H2: yes
A3: Id2 | B3: 30.36 | C3: 5.77 | D3: No | E3: No | F3: No | G3: No major surgery | H3: yes
A4: Id3 | B4: 34.485 | C4: 11.87 | D4: yes | E4: No | F4: No | G4: 2 | H4: yes
A5: Id4 | B5: 38.095 | C5: 6.05 | D5: No | E5: No | F5: No | G5: No major surgery | H5: yes
A6: Id5 | B6: 35.53 | C6: 5.45 | D6: No | E6: No | F6: No | G6: No major surgery | H6: yes
A7: Id6 | B7: 32.8 | C7: 6.59 | D7: No | E7: No | F7: No | G7: No major surgery | H7: yes
A8: Id7 | B8: 36.4 | C8: 6.07 | D8: No | E8: No | F8: No | G8: No major surgery | H8: yes
A9: Id8 | B9: 36.96 | C9: 7.93 | D9: No | E9: No | F9: No | G9: 3 | H9: yes
A10: Id9 | B10: 41.14 | C10: 9.58 | D10: yes | E10: No | F10: Yes | G10: 1 | H10: yes
A11: Id10 | B11: 38.06 | C11: 10.79 | D11: No | E11: No | F11: No | G11: No major surgery | H11: yes
A12: Id11 | B12: 37.7 | C12: 5.96 | D12: yes | E12: No | F12: No | G12: 2 | H12: yes
A13: Id12 | B13: 42.13 | C13: 11.9 | D13: No | E13: No | F13: No | G13: No major surgery | H13: yes
A14: Id13 | B14: 40.92 | C14: 8.41 | D14: No | E14: No | F14: No | G14: No major surgery | H14: yes
A15: Id14 | B15: 40.565 | C15: 7.02 | D15: No | E15: No | F15: No | G15: No major surgery | H15: yes
A16: Id15 | B16: 36.385 | C16: 7.59 | D16: yes | E16: No | F16: No | G16: 2 | H16: yes
A17: Id16 | B17: 39.9 | C17: 11.32 | D17: No | E17: No | F17: No | G17: No major surgery | H17: yes
A18: Id17 | B18: 33.8 | C18: 7.67 | D18: No | E18: No | F18: No | G18: 3 | H18: yes
A19: Id18 | B19: 36.765 | C19: 7.29 | D19: yes | E19: No | F19: Yes | G19: 1 | H19: yes
A20: Id19 | B20: 36.955 | C20: 4.72 | D20: yes | E20: No | F20: No | G20: 1 | H20: yes
A21: Id20 | B21: 42.9 | C21: 11.41 | D21: No | E21: No | F21: No | G21: No major surgery | H21: yes
A22: Id21 | B22: 36.3 | C22: 11.5 | D22: yes | E22: No | F22: No | G22: 2 | H22: yes
A23: Id22 | B23: 32.2 | C23: 6.22 | D23: yes | E23: No | F23: No | G23: 2 | H23: yes
A24: Id23 | B24: 31.3 | C24: 11.38 | D24: No | E24: No | F24: No | G24: 3 | H24: yes
A25: Id24 | B25: 41.8 | C25: 7.89 | D25: yes | E25: No | F25: No | G25: 2 | H25: yes
A26: Id25 | B26: 35.09 | C26: 4.38 | D26: yes | E26: No | F26: No | G26: 2 | H26: yes
A27: Id26 | B27: 33.88 | C27: 7.01 | D27: No | E27: No | F27: No | G27: 3 | H27: yes
A28: Id27 | B28: 30.875 | C28: 11.88 | D28: No | E28: No | F28: No | G28: No major surgery | H28: yes
A29: Id28 | B29: 36.86 | C29: 5.19 | D29: yes | E29: No | F29: Yes | G29: 1 | H29: yes
A30: Id29 | B30: 35.86 | C30: 6.74 | D30: yes | E30: No | F30: No | G30: 2 | H30: yes
A31: Id30 | B31: 37.05 | C31: 8.44 | D31: No | E31: No | F31: No | G31: No major surgery | H31: yes
A32: Id31 | B32: 43.89 | C32: 8.71 | D32: No | E32: No | F32: No | G32: No major surgery | H32: yes
A33: Id32 | B33: 42.35 | C33: 5.08 | D33: yes | E33: No | F33: No | G33: No major surgery | H33: yes
A34: Id33 | B34: 31.35 | C34: 6.86 | D34: No | E34: No | F34: No | G34: No major surgery | H34: yes
A35: Id34 | B35: 47.6 | C35: 5.95 | D35: yes | E35: No | F35: No | G35: No major surgery | H35: yes
A36: Id35 | B36: 46.2 | C36: 6.09 | D36: No | E36: No | F36: Yes | G36: 1 | H36: yes
A37: Id36 | B37: 32.015 | C37: 11.75 | D37: No | E37: No | F37: No | G37: No major surgery | H37: yes
A38: Id37 | B38: 40.565 | C38: 7.37 | D38: No | E38: No | F38: No | G38: No major surgery | H38: yes
A39: Id38 | B39: 32.45 | C39: 11.91 | D39: No | E39: No | F39: No | G39: No major surgery | H39: yes
A40: Id39 | B40: 34.96 | C40: 6.52 | D40: No | E40: No | F40: No | G40: No major surgery | H40: yes
...

Sheet Hospitalisation Details
A1: Customer ID | B1: year | C1: month | D1: date | E1: children | F1: charges | G1: Hospital tier | H1: City tier | I1: State ID
A2: Id2335 | B2: 1992 | C2: Jul | D2: 9 | E2: 0 | F2: 563.84 | G2: tier - 2 | H2: tier - 3 | I2: R1013
A3: Id2334 | B3: 1992 | C3: Nov | D3: 30 | E3: 0 | F3: 570.62 | G3: tier - 2 | H3: tier - 1 | I3: R1013
A4: Id2333 | B4: 1993 | C4: Jun | D4: 30 | E4: 0 | F4: 600 | G4: tier - 2 | H4: tier - 1 | I4: R1013
A5: Id2332 | B5: 1992 | C5: Sep | D5: 13 | E5: 0 | F5: 604.54 | G5: tier - 3 | H5: tier - 3 | I5: R1013
A6: Id2331 | B6: 1998 | C6: Jul | D6: 27 | E6: 0 | F6: 637.26 | G6: tier - 3 | H6: tier - 3 | I6: R1013
A7: Id2330 | B7: 2001 | C7: Nov | D7: 20 | E7: 0 | F7: 646.14 | G7: tier - 3 | H7: tier - 3 | I7: R1012
A8: Id2329 | B8: 1993 | C8: Jun | D8: 1 | E8: 0 | F8: 650 | G8: tier - 3 | H8: tier - 3 | I8: R1013
A9: Id2328 | B9: 1995 | C9: Jul | D9: 4 | E9: 0 | F9: 650 | G9: tier - 3 | H9: tier - 3 | I9: R1013
A10: Id2327 | B10: 2002 | C10: Nov | D10: 29 | E10: 0 | F10: 668 | G10: tier - 3 | H10: tier - 2 | I10: R1012
A11: Id2326 | B11: 1997 | C11: Nov | D11: 9 | E11: 0 | F11: 670 | G11: tier - 3 | H11: tier - 3 | I11: R1013
A12: Id2325 | B12: 2001 | C12: Sep | D12: 12 | E12: 0 | F12: 687.54 | G12: tier - 3 | H12: tier - 2 | I12: R1013
A13: Id2324 | B13: 1999 | C13: Dec | D13: 26 | E13: 0 | F13: 700 | G13: tier - 2 | H13: tier - 3 | I13: R1013
... A1050: Id1290 | B1050: 1977 | C1050: Jul | D1050: 26 | E1050: 2 | F1050: 8527.53 | G1050: tier - 2 | H1050: tier - 2 | I1050: R1013
A1051: Id1289 | B1051: ? | C1051: Jul | D1051: 24 | E1051: 0 | F1051: 8534.67 | G1051: tier - 2 | H1051: tier - 3 | I1051: R1024
A1052: Id1288 | B1052: 1981 | C1052: Dec | D1052: 27 | E1052: 3 | F1052: 8538.29 | G1052: tier - 2 | H1052: tier - 3 | I1052: R1024
A1053: Id1287 | B1053: 1975 | C1053: Nov | D1053: 6 | E1053: 1 | F1053: 8539.67 | G1053: tier - 2 | H1053: tier - 3 | I1053: R1011
A1054: Id1286 | B1054: ? | C1054: Dec | D1054: 12 | E1054: 1 | F1054: 8547.69 | G1054: tier - 2 | H1054: tier - 1 | I1054: R1013
A1055: Id1285 | B1055: 1975 | C1055: Aug | D1055: 6 | E1055: 1 | F1055: 8551.35 | G1055: tier - 2 | H1055: tier - 2 | I1055: R1011
A1056: Id1284 | B1056: 1975 | C1056: Aug | D1056: 21 | E1056: 1 | F1056: 8556.91 | G1056: tier - 2 | H1056: tier - 1 | I1056: R1011
A1057: Id1283 | B1057: 1988 | C1057: Sep | D1057: 21 | E1057: 3 | F1057: 8567.25 | G1057: tier - 2 | H1057: tier - 1 | I1057: R1012
A1058: Id1282 | B1058: 1975 | C1058: Sep | D1058: 26 | E1058: 1 | F1058: 8569.86 | G1058: tier - 2 | H1058: tier - 3 | I1058: R1013
A1059: Id1281 | B1059: 1982 | C1059: Dec | D1059: 6 | E1059: 3 | F1059: 8572.04 | G1059: tier - 2 | H1059: tier - 2 | I1059: R1021
A1060: Id1280 | B1060: 1987 | C1060: Nov | D1060: 11 | E1060: 3 | F1060: 8573.3 | G1060: tier - 2 | H1060: tier - 2 | I1060: R1021
A1061: Id1279 | B1061: 1983 | C1061: Dec | D1061: 30 | E1061: 5 | F1061: 8582.3 | G1061: tier - 2 | H1061: tier - 1 | I1061: R1013
A1062: Id1278 | B1062: 1983 | C1062: Jul | D1062: 25 | E1062: 5 | F1062: 8596.83 | G1062: tier - 2 | H1062: tier - 3 | I1062: R1013
A1063: Id1277 | B1063: 1973 | C1063: Jul | D1063: 11 | E1063: 0 | F1063: 8601.33 | G1063: tier - 2 | H1063: tier - 1 | I1063: R1013
A1064: Id1276 | B1064: 1977 | C1064: Sep | D1064: 24 | E1064: 2 | F1064: 8603.82 | G1064: tier - 2 | H1064: tier - 1 | I1064: R1019
A1065: Id1275 | B1065: 1977 | C1065: Nov | D1065: 12 | E1065: 2 | F1065: 8604.48 | G1065: tier - 3 | H1065: tier - 2 | I1065: R1016
A1066: Id1274 | B1066: 1977 | C1066: Oct | D1066: 15 | E1066: 3 | F1066: 8605.36 | G1066: tier - 2 | H1066: tier - 2 | I1066: R1013
... A2344: Id1 | B2344: 1968 | C2344: Oct | D2344: 12 | E2344: 0 | F2344: 63770.43 | G2344: tier - 1 | H2344: tier - 3 | I2344: R1013

Sheet Answers - Data Cleaning
A1: Data Cleaning
A2: 1. Missing Values | T2: 2. Fill in the missing values of month and Year | W2: Fill Missing Smoker, Hospital Tier, City Tier | AF2: Missing State ID
A3: Medical Examination Tab | J3: Hospitalisation Details | T3: Find & Replace | U3: Average year: | W3: Smoker List | Z3: Hospital tier | AC3: City tier
A4: Customer ID | B4: BMI | C4: HBA1C | D4: Heart Issues | E4: Any Transplants | F4: Cancer history | G4: NumberOfMajorSurgeries | H4: smoker | J4: Customer ID | K4: year | L4: month | M4: date | N4: children | O4: charges | P4: Hospital tier | Q4: City tier | R4: State ID | U4: =ROUND(AVERAGE('Hospitalisation Details'!B:B),0) -> 1983 | W4: Row Labels | X4: Count of smoker | Z4: Row Labels | AA4: Count of Hospital tier | AC4: Row Labels | AD4: Count of City tier | AF4: State ID | AG4: State ID
A5: =COUNTIF('Medical Examinations'!A:A,"?") -> 0 | B5: =COUNTIF('Medical Examinations'!B:B,"?") -> 0 | C5: =COUNTIF('Medical Examinations'!C:C,"?") -> 0 | D5: =COUNTIF('Medical Examinations'!D:D,"?") -> 0 | E5: =COUNTIF('Medical Examinations'!E:E,"?") -> 0 | F5: =COUNTIF('Medical Examinations'!F:F,"?") -> 0 | G5: =COUNTIF('Medical Examinations'!G:G,"?") -> 0 | H5: =COUNTIF('Medical Examinations'!H:H,"?") -> 0 | J5: =COUNTIF('Hospitalisation Details'!A:A,"?") -> 6 | K5: =COUNTIF('Hospitalisation Details'!B:B,"?") -> 2 | L5: =COUNTIF('Hospitalisation Details'!C:C,"?") -> 3 | M5: =COUNTIF('Hospitalisation Details'!D:D,"?") -> 0 | N5: =COUNTIF('Hospitalisation Details'!E:E,"?") -> 0 | O5: =COUNTIF('Hospitalisation Details'!F:F,"?") -> 0 | P5: =COUNTIF('Hospitalisation Details'!G:G,"?") -> 0 | Q5: =COUNTIF('Hospitalisation Details'!H:H,"?") -> 0 | R5: =COUNTIF('Hospitalisation Details'!I:I,"?") -> 2 | W5: No | X5: 1845 | Z5: tier - 1 | AA5: 309 | AC5: tier - 1 | AD5: 734 | AF5: R1013 | AG5: =IF(AF5="?","Unknown",AF5) -> R1013
T6: month | U6: year | W6: yes | X6: 490 | Z6: tier - 2 | AA6: 1340 | AC6: tier - 2 | AD6: 813 | AF6: R1013 | AG6: =IF(AF6="?","Unknown",AF6) -> R1013
T7: Jul | U7: 1992 | W7: (blank) | Z7: tier - 3 | AA7: 694 | AC7: tier - 3 | AD7: 796 | AF7: R1013 | AG7: =IF(AF7="?","Unknown",AF7) -> R1013
T8: Nov | U8: 1992 | W8: Grand Total | X8: 2335 | Z8: (blank) | AC8: (blank) | AF8: R1013 | AG8: =IF(AF8="?","Unknown",AF8) -> R1013
T9: Jun | U9: 1993 | Z9: Grand Total | AA9: 2343 | AC9: Grand Total | AD9: 2343 | AF9: R1013 | AG9: =IF(AF9="?","Unknown",AF9) -> R1013
T10: Sep | U10: 1992 | AF10: R1012 | AG10: =IF(AF10="?","Unknown",AF10) -> R1012
T11: Jul | U11: 1998 | AF11: R1013 | AG11: =IF(AF11="?","Unknown",AF11) -> R1013
T12: Nov | U12: 2001 | AF12: R1013 | AG12: =IF(AF12="?","Unknown",AF12) -> R1013
T13: Jun | U13: 1993 | AF13: R1012 | AG13: =IF(AF13="?","Unknown",AF13) -> R1012
T14: Jul | U14: 1995 | AF14: R1013 | AG14: =IF(AF14="?","Unknown",AF14) -> R1013
T15: Nov | U15: 2002 | AF15: R1013 | AG15: =IF(AF15="?","Unknown",AF15) -> R1013
T16: Nov | U16: 1997 | AF16: R1013 | AG16: =IF(AF16="?","Unknown",AF16) -> R1013
T17: Sep | U17: 2001 | AF17: R1013 | AG17: =IF(AF17="?","Unknown",AF17) -> R1013
T18: Dec | U18: 1999 | AF18: R1012 | AG18: =IF(AF18="?","Unknown",AF18) -> R1012
T19: Dec | U19: 1999 | AF19: R1013 | AG19: =IF(AF19="?","Unknown",AF19) -> R1013
T20: Sep | U20: 2002 | AF20: R1013 | AG20: =IF(AF20="?","Unknown",AF20) -> R1013
T21: Aug | U21: 1993 | AF21: R1013 | AG21: =IF(AF21="?","Unknown",AF21) -> R1013
... T2347: Sep | U2347: 1970 | AF2347: R1013 | AG2347: =IF(AF2347="?","Unknown",AF2347) -> R1013
T2348: Jun | U2348: 1977
T2349: Oct | U2349: 1968

Sheet Answers - Data Transformation  
A1: Data Transformation:
A3: Split the ‘names’ | F3: Convert Data | J3: Correcting inconsistencies | N3: Categorization | T3: Merger | Y3: Calucations | AA3: Formatting
A4: name | B4: Title | C4: First Name | D4: Last Name | F4: NumberOfMajorSurgeries | G4: Numeric Data | J4: Heart Issues | K4: smoker | N4: BMI | O4: Weight Status | Q4: HBA1C | R4: Diabetes Status | T4: year | U4: month | V4: date | W4: Date of Birth | Y4: Age | AA4: charges
A5: Hawks, Ms. Kelly | B5: =TRIM(MID(A5,FIND(",",A5)+1,FIND(".",A5)-FIND(",",A5)-1)) -> Ms | C5: =LEFT(A5,FIND(",",A5)-1) -> Hawks | D5: =RIGHT(A5,FIND(",",A5)-1) -> Kelly | F5: No major surgery | G5: =IF(F5="No major surgery",0,F5) -> 0 | H5: Here I gave "0" to No major Surgery . | J5: =PROPER('Medical Examinations'!D:D) -> No | K5: =PROPER('Medical Examinations'!H:H) -> Yes | L5: Here I updated data into proper case | N5: 47.41 | O5: =IF(N5<18.5,"Underweight", IF(N5<25,"Normal Weight", IF(N5<30,"Overweight", "Obesity"))) -> Obesity | Q5: 7.47 | R5: =IF(Q5<5.7,"Normal", IF(Q5<=6.4,"Prediabetes", "Diabetes")) -> Diabetes | T5: 1992 | U5: Jul | V5: 9 | W5: =DATE(T5,MONTH(1&U5),V5) -> 33794 | Y5: =DATEDIF(W5,DATE(2023,6,8),"Y") -> 30 | AA5: 563.84
A6: Lehner, Mr. Matthew D | B6: =TRIM(MID(A6,FIND(",",A6)+1,FIND(".",A6)-FIND(",",A6)-1)) -> Mr | C6: =LEFT(A6,FIND(",",A6)-1) -> Lehner | D6: =RIGHT(A6,FIND(",",A6)-1) -> thew D | F6: No major surgery | G6: =IF(F6="No major surgery",0,F6) -> 0 | J6: =PROPER('Medical Examinations'!D:D) -> No | K6: =PROPER('Medical Examinations'!H:H) -> Yes | N6: 30.36 | O6: =IF(N6<18.5,"Underweight", IF(N6<25,"Normal Weight", IF(N6<30,"Overweight", "Obesity"))) -> Obesity | Q6: 5.77 | R6: =IF(Q6<5.7,"Normal", IF(Q6<=6.4,"Prediabetes", "Diabetes")) -> Prediabetes | T6: 1992 | U6: Nov | V6: 30 | W6: =DATE(T6,MONTH(1&U6),V6) -> 33938 | Y6: =DATEDIF(W6,DATE(2023,6,8),"Y") -> 30 | AA6: 570.62
A7: Lu, Mr. Phil | B7: =TRIM(MID(A7,FIND(",",A7)+1,FIND(".",A7)-FIND(",",A7)-1)) -> Mr | C7: =LEFT(A7,FIND(",",A7)-1) -> Lu | D7: =RIGHT(A7,FIND(",",A7)-1) -> il | F7: 2 | G7: =IF(F7="No major surgery",0,F7) -> 2 | J7: =PROPER('Medical Examinations'!D:D) -> No | K7: =PROPER('Medical Examinations'!H:H) -> Yes | N7: 34.485 | O7: =IF(N7<18.5,"Underweight", IF(N7<25,"Normal Weight", IF(N7<30,"Overweight", "Obesity"))) -> Obesity | Q7: 11.87 | R7: =IF(Q7<5.7,"Normal", IF(Q7<=6.4,"Prediabetes", "Diabetes")) -> Diabetes | T7: 1993 | U7: Jun | V7: 30 | W7: =DATE(T7,MONTH(1&U7),V7) -> 34150 | Y7: =DATEDIF(W7,DATE(2023,6,8),"Y") -> 29 | AA7: 600
A8: Osborne, Ms. Kelsey | B8: =TRIM(MID(A8,FIND(",",A8)+1,FIND(".",A8)-FIND(",",A8)-1)) -> Ms | C8: =LEFT(A8,FIND(",",A8)-1) -> Osborne | D8: =RIGHT(A8,FIND(",",A8)-1) -> Kelsey | F8: No major surgery | G8: =IF(F8="No major surgery",0,F8) -> 0 | J8: =PROPER('Medical Examinations'!D:D) -> No | K8: =PROPER('Medical Examinations'!H:H) -> Yes | N8: 38.095 | O8: =IF(N8<18.5,"Underweight", IF(N8<25,"Normal Weight", IF(N8<30,"Overweight", "Obesity"))) -> Obesity | Q8: 6.05 | R8: =IF(Q8<5.7,"Normal", IF(Q8<=6.4,"Prediabetes", "Diabetes")) -> Prediabetes | T8: 1992 | U8: Sep | V8: 13 | W8: =DATE(T8,MONTH(1&U8),V8) -> 33860 | Y8: =DATEDIF(W8,DATE(2023,6,8),"Y") -> 30 | AA8: 604.54
A9: Kadala, Ms. Kristyn | B9: =TRIM(MID(A9,FIND(",",A9)+1,FIND(".",A9)-FIND(",",A9)-1)) -> Ms | C9: =LEFT(A9,FIND(",",A9)-1) -> Kadala | D9: =RIGHT(A9,FIND(",",A9)-1) -> ristyn | F9: No major surgery | G9: =IF(F9="No major surgery",0,F9) -> 0 | J9: =PROPER('Medical Examinations'!D:D) -> No | K9: =PROPER('Medical Examinations'!H:H) -> Yes | N9: 35.53 | O9: =IF(N9<18.5,"Underweight", IF(N9<25,"Normal Weight", IF(N9<30,"Overweight", "Obesity"))) -> Obesity | Q9: 5.45 | R9: =IF(Q9<5.7,"Normal", IF(Q9<=6.4,"Prediabetes", "Diabetes")) -> Normal | T9: 1998 | U9: Jul | V9: 27 | W9: =DATE(T9,MONTH(1&U9),V9) -> 36003 | Y9: =DATEDIF(W9,DATE(2023,6,8),"Y") -> 24 | AA9: 637.26
A10: Baker, Mr. Russell B. | B10: =TRIM(MID(A10,FIND(",",A10)+1,FIND(".",A10)-FIND(",",A10)-1)) -> Mr | C10: =LEFT(A10,FIND(",",A10)-1) -> Baker | D10: =RIGHT(A10,FIND(",",A10)-1) -> ll B. | F10: No major surgery | G10: =IF(F10="No major surgery",0,F10) -> 0 | J10: =PROPER('Medical Examinations'!D:D) -> Yes | K10: =PROPER('Medical Examinations'!H:H) -> Yes | N10: 32.8 | O10: =IF(N10<18.5,"Underweight", IF(N10<25,"Normal Weight", IF(N10<30,"Overweight", "Obesity"))) -> Obesity | Q10: 6.59 | R10: =IF(Q10<5.7,"Normal", IF(Q10<=6.4,"Prediabetes", "Diabetes")) -> Diabetes | T10: 2001 | U10: Nov | V10: 20 | W10: =DATE(T10,MONTH(1&U10),V10) -> 37215 | Y10: =DATEDIF(W10,DATE(2023,6,8),"Y") -> 21 | AA10: 646.14
A11: Macpherson, Mr. Scott | B11: =TRIM(MID(A11,FIND(",",A11)+1,FIND(".",A11)-FIND(",",A11)-1)) -> Mr | C11: =LEFT(A11,FIND(",",A11)-1) -> Macpherson | D11: =RIGHT(A11,FIND(",",A11)-1) -> Mr. Scott | F11: No major surgery | G11: =IF(F11="No major surgery",0,F11) -> 0 | J11: =PROPER('Medical Examinations'!D:D) -> No | K11: =PROPER('Medical Examinations'!H:H) -> Yes | N11: 36.4 | O11: =IF(N11<18.5,"Underweight", IF(N11<25,"Normal Weight", IF(N11<30,"Overweight", "Obesity"))) -> Obesity | Q11: 6.07 | R11: =IF(Q11<5.7,"Normal", IF(Q11<=6.4,"Prediabetes", "Diabetes")) -> Prediabetes | T11: 1993 | U11: Jun | V11: 1 | W11: =DATE(T11,MONTH(1&U11),V11) -> 34121 | Y11: =DATEDIF(W11,DATE(2023,6,8),"Y") -> 30 | AA11: 650
A12: Hallman, Mr. Stephen | B12: =TRIM(MID(A12,FIND(",",A12)+1,FIND(".",A12)-FIND(",",A12)-1)) -> Mr | C12: =LEFT(A12,FIND(",",A12)-1) -> Hallman | D12: =RIGHT(A12,FIND(",",A12)-1) -> Stephen | F12: 3 | G12: =IF(F12="No major surgery",0,F12) -> 3 | J12: =PROPER('Medical Examinations'!D:D) -> Yes | K12: =PROPER('Medical Examinations'!H:H) -> Yes | N12: 36.96 | O12: =IF(N12<18.5,"Underweight", IF(N12<25,"Normal Weight", IF(N12<30,"Overweight", "Obesity"))) -> Obesity | Q12: 7.93 | R12: =IF(Q12<5.7,"Normal", IF(Q12<=6.4,"Prediabetes", "Diabetes")) -> Diabetes | T12: 1995 | U12: Jul | V12: 4 | W12: =DATE(T12,MONTH(1&U12),V12) -> 34884 | Y12: =DATEDIF(W12,DATE(2023,6,8),"Y") -> 27 | AA12: 650
A13: Moran, Mr. Patrick R. | B13: =TRIM(MID(A13,FIND(",",A13)+1,FIND(".",A13)-FIND(",",A13)-1)) -> Mr | C13: =LEFT(A13,FIND(",",A13)-1) -> Moran | D13: =RIGHT(A13,FIND(",",A13)-1) -> ck R. | F13: 1 | G13: =IF(F13="No major surgery",0,F13) -> 1 | J13: =PROPER('Medical Examinations'!D:D) -> No | K13: =PROPER('Medical Examinations'!H:H) -> Yes | N13: 41.14 | O13: =IF(N13<18.5,"Underweight", IF(N13<25,"Normal Weight", IF(N13<30,"Overweight", "Obesity"))) -> Obesity | Q13: 9.58 | R13: =IF(Q13<5.7,"Normal", IF(Q13<=6.4,"Prediabetes", "Diabetes")) -> Diabetes | T13: 2002 | U13: Nov | V13: 29 | W13: =DATE(T13,MONTH(1&U13),V13) -> 37589 | Y13: =DATEDIF(W13,DATE(2023,6,8),"Y") -> 20 | AA13: 668
A14: Benner, Ms. Brooke N. | B14: =TRIM(MID(A14,FIND(",",A14)+1,FIND(".",A14)-FIND(",",A14)-1)) -> Ms | C14: =LEFT(A14,FIND(",",A14)-1) -> Benner | D14: =RIGHT(A14,FIND(",",A14)-1) -> oke N. | F14: No major surgery | G14: =IF(F14="No major surgery",0,F14) -> 0 | J14: =PROPER('Medical Examinations'!D:D) -> No | K14: =PROPER('Medical Examinations'!H:H) -> Yes | N14: 38.06 | O14: =IF(N14<18.5,"Underweight", IF(N14<25,"Normal Weight", IF(N14<30,"Overweight", "Obesity"))) -> Obesity | Q14: 10.79 | R14: =IF(Q14<5.7,"Normal", IF(Q14<=6.4,"Prediabetes", "Diabetes")) -> Diabetes | T14: 1997 | U14: Nov | V14: 9 | W14: =DATE(T14,MONTH(1&U14),V14) -> 35743 | Y14: =DATEDIF(W14,DATE(2023,6,8),"Y") -> 25 | AA14: 670
A15: Fierro Vargas, Ms. Paola Andrea | B15: =TRIM(MID(A15,FIND(",",A15)+1,FIND(".",A15)-FIND(",",A15)-1)) -> Ms | C15: =LEFT(A15,FIND(",",A15)-1) -> Fierro Vargas | D15: =RIGHT(A15,FIND(",",A15)-1) -> Paola Andrea | F15: 2 | G15: =IF(F15="No major surgery",0,F15) -> 2 | J15: =PROPER('Medical Examinations'!D:D) -> No | K15: =PROPER('Medical Examinations'!H:H) -> Yes | N15: 37.7 | O15: =IF(N15<18.5,"Underweight", IF(N15<25,"Normal Weight", IF(N15<30,"Overweight", "Obesity"))) -> Obesity | Q15: 5.96 | R15: =IF(Q15<5.7,"Normal", IF(Q15<=6.4,"Prediabetes", "Diabetes")) -> Prediabetes | T15: 2001 | U15: Sep | V15: 12 | W15: =DATE(T15,MONTH(1&U15),V15) -> 37146 | Y15: =DATEDIF(W15,DATE(2023,6,8),"Y") -> 21 | AA15: 687.54
A16: Franz, Mr. David | B16: =TRIM(MID(A16,FIND(",",A16)+1,FIND(".",A16)-FIND(",",A16)-1)) -> Mr | C16: =LEFT(A16,FIND(",",A16)-1) -> Franz | D16: =RIGHT(A16,FIND(",",A16)-1) -> David | F16: No major surgery | G16: =IF(F16="No major surgery",0,F16) -> 0 | J16: =PROPER('Medical Examinations'!D:D) -> Yes | K16: =PROPER('Medical Examinations'!H:H) -> Yes | N16: 42.13 | O16: =IF(N16<18.5,"Underweight", IF(N16<25,"Normal Weight", IF(N16<30,"Overweight", "Obesity"))) -> Obesity | Q16: 11.9 | R16: =IF(Q16<5.7,"Normal", IF(Q16<=6.4,"Prediabetes", "Diabetes")) -> Diabetes | T16: 1999 | U16: Dec | V16: 26 | W16: =DATE(T16,MONTH(1&U16),V16) -> 36520 | Y16: =DATEDIF(W16,DATE(2023,6,8),"Y") -> 23 | AA16: 700
A17: Foster, Mr. Wade | B17: =TRIM(MID(A17,FIND(",",A17)+1,FIND(".",A17)-FIND(",",A17)-1)) -> Mr | C17: =LEFT(A17,FIND(",",A17)-1) -> Foster | D17: =RIGHT(A17,FIND(",",A17)-1) -> Wade | F17: No major surgery | G17: =IF(F17="No major surgery",0,F17) -> 0 | J17: =PROPER('Medical Examinations'!D:D) -> No | K17: =PROPER('Medical Examinations'!H:H) -> Yes | N17: 40.92 | O17: =IF(N17<18.5,"Underweight", IF(N17<25,"Normal Weight", IF(N17<30,"Overweight", "Obesity"))) -> Obesity | Q17: 8.41 | R17: =IF(Q17<5.7,"Normal", IF(Q17<=6.4,"Prediabetes", "Diabetes")) -> Diabetes | T17: 1999 | U17: Dec | V17: 14 | W17: =DATE(T17,MONTH(1&U17),V17) -> 36508 | Y17: =DATEDIF(W17,DATE(2023,6,8),"Y") -> 23 | AA17: 722.99
A18: Tenorio, Mr. Franklin | B18: =TRIM(MID(A18,FIND(",",A18)+1,FIND(".",A18)-FIND(",",A18)-1)) -> Mr | C18: =LEFT(A18,FIND(",",A18)-1) -> Tenorio | D18: =RIGHT(A18,FIND(",",A18)-1) -> ranklin | F18: No major surgery | G18: =IF(F18="No major surgery",0,F18) -> 0 | J18: =PROPER('Medical Examinations'!D:D) -> No | K18: =PROPER('Medical Examinations'!H:H) -> Yes | N18: 40.565 | O18: =IF(N18<18.5,"Underweight", IF(N18<25,"Normal Weight", IF(N18<30,"Overweight", "Obesity"))) -> Obesity | Q18: 7.02 | R18: =IF(Q18<5.7,"Normal", IF(Q18<=6.4,"Prediabetes", "Diabetes")) -> Diabetes | T18: 2002 | U18: Sep | V18: 19 | W18: =DATE(T18,MONTH(1&U18),V18) -> 37518 | Y18: =DATEDIF(W18,DATE(2023,6,8),"Y") -> 20 | AA18: 750
A19: Rios, Ms. Leilani M. | B19: =TRIM(MID(A19,FIND(",",A19)+1,FIND(".",A19)-FIND(",",A19)-1)) -> Ms | C19: =LEFT(A19,FIND(",",A19)-1) -> Rios | D19: =RIGHT(A19,FIND(",",A19)-1) -> i M. | F19: 2 | G19: =IF(F19="No major surgery",0,F19) -> 2 | J19: =PROPER('Medical Examinations'!D:D) -> Yes | K19: =PROPER('Medical Examinations'!H:H) -> Yes | N19: 36.385 | O19: =IF(N19<18.5,"Underweight", IF(N19<25,"Normal Weight", IF(N19<30,"Overweight", "Obesity"))) -> Obesity | Q19: 7.59 | R19: =IF(Q19<5.7,"Normal", IF(Q19<=6.4,"Prediabetes", "Diabetes")) -> Diabetes | T19: 1993 | U19: Aug | V19: 9 | W19: =DATE(T19,MONTH(1&U19),V19) -> 34190 | Y19: =DATEDIF(W19,DATE(2023,6,8),"Y") -> 29 | AA19: 760
A20: Viau-Dupuis, Mr. Philippe | B20: =TRIM(MID(A20,FIND(",",A20)+1,FIND(".",A20)-FIND(",",A20)-1)) -> Mr | C20: =LEFT(A20,FIND(",",A20)-1) -> Viau-Dupuis | D20: =RIGHT(A20,FIND(",",A20)-1) -> . Philippe | F20: No major surgery | G20: =IF(F20="No major surgery",0,F20) -> 0 | J20: =PROPER('Medical Examinations'!D:D) -> Yes | K20: =PROPER('Medical Examinations'!H:H) -> Yes | N20: 39.9 | O20: =IF(N20<18.5,"Underweight", IF(N20<25,"Normal Weight", IF(N20<30,"Overweight", "Obesity"))) -> Obesity | Q20: 11.32 | R20: =IF(Q20<5.7,"Normal", IF(Q20<=6.4,"Prediabetes", "Diabetes")) -> Diabetes | T20: 1996 | U20: Oct | V20: 22 | W20: =DATE(T20,MONTH(1&U20),V20) -> 35360 | Y20: =DATEDIF(W20,DATE(2023,6,8),"Y") -> 26 | AA20: 760
A21: Cronin, Ms. Jennifer A. | B21: =TRIM(MID(A21,FIND(",",A21)+1,FIND(".",A21)-FIND(",",A21)-1)) -> Ms | C21: =LEFT(A21,FIND(",",A21)-1) -> Cronin | D21: =RIGHT(A21,FIND(",",A21)-1) -> fer A. | F21: 3 | G21: =IF(F21="No major surgery",0,F21) -> 3 | J21: =PROPER('Medical Examinations'!D:D) -> No | K21: =PROPER('Medical Examinations'!H:H) -> Yes | N21: 33.8 | O21: =IF(N21<18.5,"Underweight", IF(N21<25,"Normal Weight", IF(N21<30,"Overweight", "Obesity"))) -> Obesity | Q21: 7.67 | R21: =IF(Q21<5.7,"Normal", IF(Q21<=6.4,"Prediabetes", "Diabetes")) -> Diabetes | T21: 1993 | U21: Jun | V21: 28 | W21: =DATE(T21,MONTH(1&U21),V21) -> 34148 | Y21: =DATEDIF(W21,DATE(2023,6,8),"Y") -> 29 | AA21: 770
A22: Noordstar, Ms. Christina M. | B22: =TRIM(MID(A22,FIND(",",A22)+1,FIND(".",A22)-FIND(",",A22)-1)) -> Ms | C22: =LEFT(A22,FIND(",",A22)-1) -> Noordstar | D22: =RIGHT(A22,FIND(",",A22)-1) -> istina M. | F22: 1 | G22: =IF(F22="No major surgery",0,F22) -> 1 | J22: =PROPER('Medical Examinations'!D:D) -> Yes | K22: =PROPER('Medical Examinations'!H:H) -> Yes | N22: 36.765 | O22: =IF(N22<18.5,"Underweight", IF(N22<25,"Normal Weight", IF(N22<30,"Overweight", "Obesity"))) -> Obesity | Q22: 7.29 | R22: =IF(Q22<5.7,"Normal", IF(Q22<=6.4,"Prediabetes", "Diabetes")) -> Diabetes | T22: 1996 | U22: Sep | V22: 18 | W22: =DATE(T22,MONTH(1&U22),V22) -> 35326 | Y22: =DATEDIF(W22,DATE(2023,6,8),"Y") -> 26 | AA22: 770.38
A23: Boudalia, Mr. Said Sr. | B23: =TRIM(MID(A23,FIND(",",A23)+1,FIND(".",A23)-FIND(",",A23)-1)) -> Mr | C23: =LEFT(A23,FIND(",",A23)-1) -> Boudalia | D23: =RIGHT(A23,FIND(",",A23)-1) -> Said Sr. | F23: 1 | G23: =IF(F23="No major surgery",0,F23) -> 1 | J23: =PROPER('Medical Examinations'!D:D) -> Yes | K23: =PROPER('Medical Examinations'!H:H) -> Yes | N23: 36.955 | O23: =IF(N23<18.5,"Underweight", IF(N23<25,"Normal Weight", IF(N23<30,"Overweight", "Obesity"))) -> Obesity | Q23: 4.72 | R23: =IF(Q23<5.7,"Normal", IF(Q23<=6.4,"Prediabetes", "Diabetes")) -> Normal | T23: 1995 | U23: Dec | V23: 7 | W23: =DATE(T23,MONTH(1&U23),V23) -> 35040 | Y23: =DATEDIF(W23,DATE(2023,6,8),"Y") -> 27 | AA23: 773.54
A24: Flor, Mr. John | B24: =TRIM(MID(A24,FIND(",",A24)+1,FIND(".",A24)-FIND(",",A24)-1)) -> Mr | C24: =LEFT(A24,FIND(",",A24)-1) -> Flor | D24: =RIGHT(A24,FIND(",",A24)-1) -> John | F24: No major surgery | G24: =IF(F24="No major surgery",0,F24) -> 0 | J24: =PROPER('Medical Examinations'!D:D) -> No | K24: =PROPER('Medical Examinations'!H:H) -> Yes | N24: 42.9 | O24: =IF(N24<18.5,"Underweight", IF(N24<25,"Normal Weight", IF(N24<30,"Overweight", "Obesity"))) -> Obesity | Q24: 11.41 | R24: =IF(Q24<5.7,"Normal", IF(Q24<=6.4,"Prediabetes", "Diabetes")) -> Diabetes | T24: 2004 | U24: Oct | V24: 7 | W24: =DATE(T24,MONTH(1&U24),V24) -> 38267 | Y24: =DATEDIF(W24,DATE(2023,6,8),"Y") -> 18 | AA24: 830.52
A25: Fennon, Mr. Myles | B25: =TRIM(MID(A25,FIND(",",A25)+1,FIND(".",A25)-FIND(",",A25)-1)) -> Mr | C25: =LEFT(A25,FIND(",",A25)-1) -> Fennon | D25: =RIGHT(A25,FIND(",",A25)-1) -> Myles | F25: 2 | G25: =IF(F25="No major surgery",0,F25) -> 2 | J25: =PROPER('Medical Examinations'!D:D) -> Yes | K25: =PROPER('Medical Examinations'!H:H) -> Yes | N25: 36.3 | O25: =IF(N25<18.5,"Underweight", IF(N25<25,"Normal Weight", IF(N25<30,"Overweight", "Obesity"))) -> Obesity | Q25: 11.5 | R25: =IF(Q25<5.7,"Normal", IF(Q25<=6.4,"Prediabetes", "Diabetes")) -> Diabetes | T25: 2000 | U25: Nov | V25: 18 | W25: =DATE(T25,MONTH(1&U25),V25) -> 36848 | Y25: =DATEDIF(W25,DATE(2023,6,8),"Y") -> 22 | AA25: 865.41
A26: Hribar, Ms. Madelyn C | B26: =TRIM(MID(A26,FIND(",",A26)+1,FIND(".",A26)-FIND(",",A26)-1)) -> Ms | C26: =LEFT(A26,FIND(",",A26)-1) -> Hribar | D26: =RIGHT(A26,FIND(",",A26)-1) -> elyn C | F26: 2 | G26: =IF(F26="No major surgery",0,F26) -> 2 | J26: =PROPER('Medical Examinations'!D:D) -> Yes | K26: =PROPER('Medical Examinations'!H:H) -> Yes | N26: 32.2 | O26: =IF(N26<18.5,"Underweight", IF(N26<25,"Normal Weight", IF(N26<30,"Overweight", "Obesity"))) -> Obesity | Q26: 6.22 | R26: =IF(Q26<5.7,"Normal", IF(Q26<=6.4,"Prediabetes", "Diabetes")) -> Prediabetes | T26: 1993 | U26: Nov | V26: 27 | W26: =DATE(T26,MONTH(1&U26),V26) -> 34300 | Y26: =DATEDIF(W26,DATE(2023,6,8),"Y") -> 29 | AA26: 896.21
A27: Tassello, Ms. Nicole | B27: =TRIM(MID(A27,FIND(",",A27)+1,FIND(".",A27)-FIND(",",A27)-1)) -> Ms | C27: =LEFT(A27,FIND(",",A27)-1) -> Tassello | D27: =RIGHT(A27,FIND(",",A27)-1) -> Nicole | F27: 3 | G27: =IF(F27="No major surgery",0,F27) -> 3 | J27: =PROPER('Medical Examinations'!D:D) -> No | K27: =PROPER('Medical Examinations'!H:H) -> Yes | N27: 31.3 | O27: =IF(N27<18.5,"Underweight", IF(N27<25,"Normal Weight", IF(N27<30,"Overweight", "Obesity"))) -> Obesity | Q27: 11.38 | R27: =IF(Q27<5.7,"Normal", IF(Q27<=6.4,"Prediabetes", "Diabetes")) -> Diabetes | T27: 1994 | U27: Oct | V27: 30 | W27: =DATE(T27,MONTH(1&U27),V27) -> 34637 | Y27: =DATEDIF(W27,DATE(2023,6,8),"Y") -> 28 | AA27: 915.07
A28: Mauricette, Mr. Eric A. | B28: =TRIM(MID(A28,FIND(",",A28)+1,FIND(".",A28)-FIND(",",A28)-1)) -> Mr | C28: =LEFT(A28,FIND(",",A28)-1) -> Mauricette | D28: =RIGHT(A28,FIND(",",A28)-1) -> . Eric A. | F28: 2 | G28: =IF(F28="No major surgery",0,F28) -> 2 | J28: =PROPER('Medical Examinations'!D:D) -> No | K28: =PROPER('Medical Examinations'!H:H) -> Yes | N28: 41.8 | O28: =IF(N28<18.5,"Underweight", IF(N28<25,"Normal Weight", IF(N28<30,"Overweight", "Obesity"))) -> Obesity | Q28: 7.89 | R28: =IF(Q28<5.7,"Normal", IF(Q28<=6.4,"Prediabetes", "Diabetes")) -> Diabetes | T28: 1995 | U28: Oct | V28: 28 | W28: =DATE(T28,MONTH(1&U28),V28) -> 35000 | Y28: =DATEDIF(W28,DATE(2023,6,8),"Y") -> 27 | AA28: 928.59
A29: Garcia, Mr. Emiliano I. | B29: =TRIM(MID(A29,FIND(",",A29)+1,FIND(".",A29)-FIND(",",A29)-1)) -> Mr | C29: =LEFT(A29,FIND(",",A29)-1) -> Garcia | D29: =RIGHT(A29,FIND(",",A29)-1) -> ano I. | F29: 2 | G29: =IF(F29="No major surgery",0,F29) -> 2 | J29: =PROPER('Medical Examinations'!D:D) -> Yes | K29: =PROPER('Medical Examinations'!H:H) -> Yes | N29: 35.09 | O29: =IF(N29<18.5,"Underweight", IF(N29<25,"Normal Weight", IF(N29<30,"Overweight", "Obesity"))) -> Obesity | Q29: 4.38 | R29: =IF(Q29<5.7,"Normal", IF(Q29<=6.4,"Prediabetes", "Diabetes")) -> Normal | T29: 2001 | U29: Aug | V29: 19 | W29: =DATE(T29,MONTH(1&U29),V29) -> 37122 | Y29: =DATEDIF(W29,DATE(2023,6,8),"Y") -> 21 | AA29: 964.71
A30: Airoldi, Mr. Adam | B30: =TRIM(MID(A30,FIND(",",A30)+1,FIND(".",A30)-FIND(",",A30)-1)) -> Mr | C30: =LEFT(A30,FIND(",",A30)-1) -> Airoldi | D30: =RIGHT(A30,FIND(",",A30)-1) -> . Adam | F30: 3 | G30: =IF(F30="No major surgery",0,F30) -> 3 | J30: =PROPER('Medical Examinations'!D:D) -> Yes | K30: =PROPER('Medical Examinations'!H:H) -> Yes | N30: 33.88 | O30: =IF(N30<18.5,"Underweight", IF(N30<25,"Normal Weight", IF(N30<30,"Overweight", "Obesity"))) -> Obesity | Q30: 7.01 | R30: =IF(Q30<5.7,"Normal", IF(Q30<=6.4,"Prediabetes", "Diabetes")) -> Diabetes | T30: 1994 | U30: Nov | V30: 22 | W30: =DATE(T30,MONTH(1&U30),V30) -> 34660 | Y30: =DATEDIF(W30,DATE(2023,6,8),"Y") -> 28 | AA30: 1006.65
A31: Cater-Cyker, Mr. Zach | B31: =TRIM(MID(A31,FIND(",",A31)+1,FIND(".",A31)-FIND(",",A31)-1)) -> Mr | C31: =LEFT(A31,FIND(",",A31)-1) -> Cater-Cyker | D31: =RIGHT(A31,FIND(",",A31)-1) -> , Mr. Zach | F31: No major surgery | G31: =IF(F31="No major surgery",0,F31) -> 0 | J31: =PROPER('Medical Examinations'!D:D) -> No | K31: =PROPER('Medical Examinations'!H:H) -> Yes | N31: 30.875 | O31: =IF(N31<18.5,"Underweight", IF(N31<25,"Normal Weight", IF(N31<30,"Overweight", "Obesity"))) -> Obesity | Q31: 11.88 | R31: =IF(Q31<5.7,"Normal", IF(Q31<=6.4,"Prediabetes", "Diabetes")) -> Diabetes | T31: 2000 | U31: Oct | V31: 9 | W31: =DATE(T31,MONTH(1&U31),V31) -> 36808 | Y31: =DATEDIF(W31,DATE(2023,6,8),"Y") -> 22 | AA31: 1012
A32: Hamm, Ms. Stephanie W. | B32: =TRIM(MID(A32,FIND(",",A32)+1,FIND(".",A32)-FIND(",",A32)-1)) -> Ms | C32: =LEFT(A32,FIND(",",A32)-1) -> Hamm | D32: =RIGHT(A32,FIND(",",A32)-1) -> e W. | F32: 1 | G32: =IF(F32="No major surgery",0,F32) -> 1 | J32: =PROPER('Medical Examinations'!D:D) -> No | K32: =PROPER('Medical Examinations'!H:H) -> Yes | N32: 36.86 | O32: =IF(N32<18.5,"Underweight", IF(N32<25,"Normal Weight", IF(N32<30,"Overweight", "Obesity"))) -> Obesity | Q32: 5.19 | R32: =IF(Q32<5.7,"Normal", IF(Q32<=6.4,"Prediabetes", "Diabetes")) -> Normal | T32: 1999 | U32: Aug | V32: 5 | W32: =DATE(T32,MONTH(1&U32),V32) -> 36377 | Y32: =DATEDIF(W32,DATE(2023,6,8),"Y") -> 23 | AA32: 1019
A33: Cox, Mr. Stephen | B33: =TRIM(MID(A33,FIND(",",A33)+1,FIND(".",A33)-FIND(",",A33)-1)) -> Mr | C33: =LEFT(A33,FIND(",",A33)-1) -> Cox | D33: =RIGHT(A33,FIND(",",A33)-1) -> hen | F33: 2 | G33: =IF(F33="No major surgery",0,F33) -> 2 | J33: =PROPER('Medical Examinations'!D:D) -> Yes | K33: =PROPER('Medical Examinations'!H:H) -> Yes | N33: 35.86 | O33: =IF(N33<18.5,"Underweight", IF(N33<25,"Normal Weight", IF(N33<30,"Overweight", "Obesity"))) -> Obesity | Q33: 6.74 | R33: =IF(Q33<5.7,"Normal", IF(Q33<=6.4,"Prediabetes", "Diabetes")) -> Diabetes | T33: 1995 | U33: Oct | V33: 5 | W33: =DATE(T33,MONTH(1&U33),V33) -> 34977 | Y33: =DATEDIF(W33,DATE(2023,6,8),"Y") -> 27 | AA33: 1033.74
A34: Sachrajda, Ms. Natalie | B34: =TRIM(MID(A34,FIND(",",A34)+1,FIND(".",A34)-FIND(",",A34)-1)) -> Ms | C34: =LEFT(A34,FIND(",",A34)-1) -> Sachrajda | D34: =RIGHT(A34,FIND(",",A34)-1) -> Natalie | F34: No major surgery | G34: =IF(F34="No major surgery",0,F34) -> 0 | J34: =PROPER('Medical Examinations'!D:D) -> No | K34: =PROPER('Medical Examinations'!H:H) -> Yes | N34: 37.05 | O34: =IF(N34<18.5,"Underweight", IF(N34<25,"Normal Weight", IF(N34<30,"Overweight", "Obesity"))) -> Obesity | Q34: 8.44 | R34: =IF(Q34<5.7,"Normal", IF(Q34<=6.4,"Prediabetes", "Diabetes")) -> Diabetes | T34: 1994 | U34: Nov | V34: 17 | W34: =DATE(T34,MONTH(1&U34),V34) -> 34655 | Y34: =DATEDIF(W34,DATE(2023,6,8),"Y") -> 28 | AA34: 1044
A35: Gareri, Ms. Nicole J. | B35: =TRIM(MID(A35,FIND(",",A35)+1,FIND(".",A35)-FIND(",",A35)-1)) -> Ms | C35: =LEFT(A35,FIND(",",A35)-1) -> Gareri | D35: =RIGHT(A35,FIND(",",A35)-1) -> ole J. | F35: No major surgery | G35: =IF(F35="No major surgery",0,F35) -> 0 | J35: =PROPER('Medical Examinations'!D:D) -> Yes | K35: =PROPER('Medical Examinations'!H:H) -> Yes | N35: 43.89 | O35: =IF(N35<18.5,"Underweight", IF(N35<25,"Normal Weight", IF(N35<30,"Overweight", "Obesity"))) -> Obesity | Q35: 8.71 | R35: =IF(Q35<5.7,"Normal", IF(Q35<=6.4,"Prediabetes", "Diabetes")) -> Diabetes | T35: 2002 | U35: Jul | V35: 20 | W35: =DATE(T35,MONTH(1&U35),V35) -> 37457 | Y35: =DATEDIF(W35,DATE(2023,6,8),"Y") -> 20 | AA35: 1047
A36: Welch, Mr. Jefferson D | B36: =TRIM(MID(A36,FIND(",",A36)+1,FIND(".",A36)-FIND(",",A36)-1)) -> Mr | C36: =LEFT(A36,FIND(",",A36)-1) -> Welch | D36: =RIGHT(A36,FIND(",",A36)-1) -> son D | F36: No major surgery | G36: =IF(F36="No major surgery",0,F36) -> 0 | J36: =PROPER('Medical Examinations'!D:D) -> No | K36: =PROPER('Medical Examinations'!H:H) -> Yes | N36: 42.35 | O36: =IF(N36<18.5,"Underweight", IF(N36<25,"Normal Weight", IF(N36<30,"Overweight", "Obesity"))) -> Obesity | Q36: 5.08 | R36: =IF(Q36<5.7,"Normal", IF(Q36<=6.4,"Prediabetes", "Diabetes")) -> Normal | T36: 2002 | U36: Jul | V36: 1 | W36: =DATE(T36,MONTH(1&U36),V36) -> 37438 | Y36: =DATEDIF(W36,DATE(2023,6,8),"Y") -> 20 | AA36: 1049
A37: Prindiville, Mr. Brendan D. | B37: =TRIM(MID(A37,FIND(",",A37)+1,FIND(".",A37)-FIND(",",A37)-1)) -> Mr | C37: =LEFT(A37,FIND(",",A37)-1) -> Prindiville | D37: =RIGHT(A37,FIND(",",A37)-1) -> Brendan D. | F37: No major surgery | G37: =IF(F37="No major surgery",0,F37) -> 0 | J37: =PROPER('Medical Examinations'!D:D) -> No | K37: =PROPER('Medical Examinations'!H:H) -> Yes | N37: 31.35 | O37: =IF(N37<18.5,"Underweight", IF(N37<25,"Normal Weight", IF(N37<30,"Overweight", "Obesity"))) -> Obesity | Q37: 6.86 | R37: =IF(Q37<5.7,"Normal", IF(Q37<=6.4,"Prediabetes", "Diabetes")) -> Diabetes | T37: 1995 | U37: Jun | V37: 1 | W37: =DATE(T37,MONTH(1&U37),V37) -> 34851 | Y37: =DATEDIF(W37,DATE(2023,6,8),"Y") -> 28 | AA37: 1056
A38: Kincaid, Ms. Courtney | B38: =TRIM(MID(A38,FIND(",",A38)+1,FIND(".",A38)-FIND(",",A38)-1)) -> Ms | C38: =LEFT(A38,FIND(",",A38)-1) -> Kincaid | D38: =RIGHT(A38,FIND(",",A38)-1) -> ourtney | F38: No major surgery | G38: =IF(F38="No major surgery",0,F38) -> 0 | J38: =PROPER('Medical Examinations'!D:D) -> No | K38: =PROPER('Medical Examinations'!H:H) -> Yes | N38: 47.6 | O38: =IF(N38<18.5,"Underweight", IF(N38<25,"Normal Weight", IF(N38<30,"Overweight", "Obesity"))) -> Obesity | Q38: 5.95 | R38: =IF(Q38<5.7,"Normal", IF(Q38<=6.4,"Prediabetes", "Diabetes")) -> Prediabetes | T38: 1993 | U38: Sep | V38: 28 | W38: =DATE(T38,MONTH(1&U38),V38) -> 34240 | Y38: =DATEDIF(W38,DATE(2023,6,8),"Y") -> 29 | AA38: 1068
A39: Bruestle, Ms. Sydney L. | B39: =TRIM(MID(A39,FIND(",",A39)+1,FIND(".",A39)-FIND(",",A39)-1)) -> Ms | C39: =LEFT(A39,FIND(",",A39)-1) -> Bruestle | D39: =RIGHT(A39,FIND(",",A39)-1) -> ydney L. | F39: 1 | G39: =IF(F39="No major surgery",0,F39) -> 1 | J39: =PROPER('Medical Examinations'!D:D) -> No | K39: =PROPER('Medical Examinations'!H:H) -> Yes | N39: 46.2 | O39: =IF(N39<18.5,"Underweight", IF(N39<25,"Normal Weight", IF(N39<30,"Overweight", "Obesity"))) -> Obesity | Q39: 6.09 | R39: =IF(Q39<5.7,"Normal", IF(Q39<=6.4,"Prediabetes", "Diabetes")) -> Prediabetes | T39: 2004 | U39: Aug | V39: 24 | W39: =DATE(T39,MONTH(1&U39),V39) -> 38223 | Y39: =DATEDIF(W39,DATE(2023,6,8),"Y") -> 18 | AA39: 1070
A40: Lachance, Mr. Julien | B40: =TRIM(MID(A40,FIND(",",A40)+1,FIND(".",A40)-FIND(",",A40)-1)) -> Mr | C40: =LEFT(A40,FIND(",",A40)-1) -> Lachance | D40: =RIGHT(A40,FIND(",",A40)-1) -> Julien | F40: No major surgery | G40: =IF(F40="No major surgery",0,F40) -> 0 | J40: =PROPER('Medical Examinations'!D:D) -> No | K40: =PROPER('Medical Examinations'!H:H) -> Yes | N40: 32.015 | O40: =IF(N40<18.5,"Underweight", IF(N40<25,"Normal Weight", IF(N40<30,"Overweight", "Obesity"))) -> Obesity | Q40: 11.75 | R40: =IF(Q40<5.7,"Normal", IF(Q40<=6.4,"Prediabetes", "Diabetes")) -> Diabetes | T40: 1997 | U40: Aug | V40: 13 | W40: =DATE(T40,MONTH(1&U40),V40) -> 35655 | Y40: =DATEDIF(W40,DATE(2023,6,8),"Y") -> 25 | AA40: 1071
A41: Eason, Mr. Ryan M | B41: =TRIM(MID(A41,FIND(",",A41)+1,FIND(".",A41)-FIND(",",A41)-1)) -> Mr | C41: =LEFT(A41,FIND(",",A41)-1) -> Eason | D41: =RIGHT(A41,FIND(",",A41)-1) -> yan M | F41: No major surgery | G41: =IF(F41="No major surgery",0,F41) -> 0 | J41: =PROPER('Medical Examinations'!D:D) -> No | K41: =PROPER('Medical Examinations'!H:H) -> Yes | N41: 40.565 | O41: =IF(N41<18.5,"Underweight", IF(N41<25,"Normal Weight", IF(N41<30,"Overweight", "Obesity"))) -> Obesity | Q41: 7.37 | R41: =IF(Q41<5.7,"Normal", IF(Q41<=6.4,"Prediabetes", "Diabetes")) -> Diabetes | T41: 1998 | U41: Dec | V41: 26 | W41: =DATE(T41,MONTH(1&U41),V41) -> 36155 | Y41: =DATEDIF(W41,DATE(2023,6,8),"Y") -> 24 | AA41: 1082
...

Sheet Healthcare
A1: Customer ID | B1: Name | C1: BMI | D1: HBA1C | E1: Heart Issues | F1: Any Transplants | G1: Cancer history | H1: NumberOfMajorSurgeries | I1: smoker | J1: year | K1: month | L1: date | M1: children | N1: charges | O1: Hospital tier | P1: City tier | Q1: State ID
A2: Id1 | B2: =VLOOKUP(A2,'Customer Names'!A:B,2,0) -> Hawks, Ms. Kelly | C2: =VLOOKUP(A2,'Medical Examinations'!A:H,2,0) -> 47.41 | D2: =VLOOKUP(A2,'Medical Examinations'!A:C,3,0) -> 7.47 | E2: =VLOOKUP(A2,'Medical Examinations'!A:E,4) -> No | F2: =VLOOKUP(A2,'Medical Examinations'!A:E,5) -> No | G2: =VLOOKUP(A2,'Medical Examinations'!A:F,6,0) -> No | H2: =VLOOKUP(A2,'Medical Examinations'!A:G,7) -> No major surgery | I2: =VLOOKUP(A2,'Medical Examinations'!A:H,8,0) -> yes | J2: =VLOOKUP(A2,'Hospitalisation Details'!A:B,2,0) -> 1968 | K2: =VLOOKUP(A2,'Hospitalisation Details'!A:C,3,0) -> Oct | L2: =VLOOKUP(A2,'Hospitalisation Details'!A:D,4,0) -> 12 | M2: =VLOOKUP(A2,'Hospitalisation Details'!A:E,5,0) -> 0 | N2: =VLOOKUP(A2,'Hospitalisation Details'!A:F,6,0) -> 63770.43 | O2: =VLOOKUP(A2,'Hospitalisation Details'!A:G,7,0) -> tier - 1 | P2: =VLOOKUP(A2,'Hospitalisation Details'!A:I,8,0) -> tier - 3 | Q2: =VLOOKUP(A2,'Hospitalisation Details'!A:I,9,0) -> R1013
A3: Id2 | B3: =VLOOKUP(A3,'Customer Names'!A:B,2,0) -> Lehner, Mr. Matthew D | C3: =VLOOKUP(A3,'Medical Examinations'!A:H,2,0) -> 30.36 | D3: =VLOOKUP(A3,'Medical Examinations'!A:C,3,0) -> 5.77 | E3: =VLOOKUP(A3,'Medical Examinations'!A:E,4) -> yes | F3: =VLOOKUP(A3,'Medical Examinations'!A:E,5) -> No | G3: =VLOOKUP(A3,'Medical Examinations'!A:F,6,0) -> No | H3: =VLOOKUP(A3,'Medical Examinations'!A:G,7) -> No major surgery | I3: =VLOOKUP(A3,'Medical Examinations'!A:H,8,0) -> yes | J3: =VLOOKUP(A3,'Hospitalisation Details'!A:B,2,0) -> 1977 | K3: =VLOOKUP(A3,'Hospitalisation Details'!A:C,3,0) -> Jun | L3: =VLOOKUP(A3,'Hospitalisation Details'!A:D,4,0) -> 8 | M3: =VLOOKUP(A3,'Hospitalisation Details'!A:E,5,0) -> 0 | N3: =VLOOKUP(A3,'Hospitalisation Details'!A:F,6,0) -> 62592.87 | O3: =VLOOKUP(A3,'Hospitalisation Details'!A:G,7,0) -> tier - 2 | P3: =VLOOKUP(A3,'Hospitalisation Details'!A:I,8,0) -> tier - 3 | Q3: =VLOOKUP(A3,'Hospitalisation Details'!A:I,9,0) -> R1013
A4: Id3 | B4: =VLOOKUP(A4,'Customer Names'!A:B,2,0) -> Lu, Mr. Phil | C4: =VLOOKUP(A4,'Medical Examinations'!A:H,2,0) -> 34.485 | D4: =VLOOKUP(A4,'Medical Examinations'!A:C,3,0) -> 11.87 | E4: =VLOOKUP(A4,'Medical Examinations'!A:E,4) -> No | F4: =VLOOKUP(A4,'Medical Examinations'!A:E,5) -> No | G4: =VLOOKUP(A4,'Medical Examinations'!A:F,6,0) -> No | H4: =VLOOKUP(A4,'Medical Examinations'!A:G,7) -> 1 | I4: =VLOOKUP(A4,'Medical Examinations'!A:H,8,0) -> yes | J4: =VLOOKUP(A4,'Hospitalisation Details'!A:B,2,0) -> 1970 | K4: Sep | L4: =VLOOKUP(A4,'Hospitalisation Details'!A:D,4,0) -> 11 | M4: =VLOOKUP(A4,'Hospitalisation Details'!A:E,5,0) -> 3 | N4: =VLOOKUP(A4,'Hospitalisation Details'!A:F,6,0) -> 60021.4 | O4: =VLOOKUP(A4,'Hospitalisation Details'!A:G,7,0) -> tier - 1 | P4: =VLOOKUP(A4,'Hospitalisation Details'!A:I,8,0) -> tier - 1 | Q4: =VLOOKUP(A4,'Hospitalisation Details'!A:I,9,0) -> R1012
A5: Id4 | B5: =VLOOKUP(A5,'Customer Names'!A:B,2,0) -> Osborne, Ms. Kelsey | C5: =VLOOKUP(A5,'Medical Examinations'!A:H,2,0) -> 38.095 | D5: =VLOOKUP(A5,'Medical Examinations'!A:C,3,0) -> 6.05 | E5: =VLOOKUP(A5,'Medical Examinations'!A:E,4) -> No | F5: =VLOOKUP(A5,'Medical Examinations'!A:E,5) -> No | G5: =VLOOKUP(A5,'Medical Examinations'!A:F,6,0) -> No | H5: =VLOOKUP(A5,'Medical Examinations'!A:G,7) -> 1 | I5: =VLOOKUP(A5,'Medical Examinations'!A:H,8,0) -> yes | J5: =VLOOKUP(A5,'Hospitalisation Details'!A:B,2,0) -> 1991 | K5: =VLOOKUP(A5,'Hospitalisation Details'!A:C,3,0) -> Jun | L5: =VLOOKUP(A5,'Hospitalisation Details'!A:D,4,0) -> 6 | M5: =VLOOKUP(A5,'Hospitalisation Details'!A:E,5,0) -> 1 | N5: =VLOOKUP(A5,'Hospitalisation Details'!A:F,6,0) -> 58571.07 | O5: =VLOOKUP(A5,'Hospitalisation Details'!A:G,7,0) -> tier - 1 | P5: =VLOOKUP(A5,'Hospitalisation Details'!A:I,8,0) -> tier - 3 | Q5: =VLOOKUP(A5,'Hospitalisation Details'!A:I,9,0) -> R1024
A6: Id5 | B6: =VLOOKUP(A6,'Customer Names'!A:B,2,0) -> Kadala, Ms. Kristyn | C6: =VLOOKUP(A6,'Medical Examinations'!A:H,2,0) -> 35.53 | D6: =VLOOKUP(A6,'Medical Examinations'!A:C,3,0) -> 5.45 | E6: =VLOOKUP(A6,'Medical Examinations'!A:E,4) -> No | F6: =VLOOKUP(A6,'Medical Examinations'!A:E,5) -> No | G6: =VLOOKUP(A6,'Medical Examinations'!A:F,6,0) -> No | H6: =VLOOKUP(A6,'Medical Examinations'!A:G,7) -> 1 | I6: =VLOOKUP(A6,'Medical Examinations'!A:H,8,0) -> yes | J6: =VLOOKUP(A6,'Hospitalisation Details'!A:B,2,0) -> 1989 | K6: =VLOOKUP(A6,'Hospitalisation Details'!A:C,3,0) -> Jun | L6: =VLOOKUP(A6,'Hospitalisation Details'!A:D,4,0) -> 19 | M6: =VLOOKUP(A6,'Hospitalisation Details'!A:E,5,0) -> 0 | N6: =VLOOKUP(A6,'Hospitalisation Details'!A:F,6,0) -> 55135.4 | O6: =VLOOKUP(A6,'Hospitalisation Details'!A:G,7,0) -> tier - 1 | P6: =VLOOKUP(A6,'Hospitalisation Details'!A:I,8,0) -> tier - 2 | Q6: =VLOOKUP(A6,'Hospitalisation Details'!A:I,9,0) -> R1012
A7: Id6 | B7: =VLOOKUP(A7,'Customer Names'!A:B,2,0) -> Baker, Mr. Russell B. | C7: =VLOOKUP(A7,'Medical Examinations'!A:H,2,0) -> 32.8 | D7: =VLOOKUP(A7,'Medical Examinations'!A:C,3,0) -> 6.59 | E7: =VLOOKUP(A7,'Medical Examinations'!A:E,4) -> No | F7: =VLOOKUP(A7,'Medical Examinations'!A:E,5) -> No | G7: =VLOOKUP(A7,'Medical Examinations'!A:F,6,0) -> No | H7: =VLOOKUP(A7,'Medical Examinations'!A:G,7) -> 1 | I7: =VLOOKUP(A7,'Medical Examinations'!A:H,8,0) -> yes | J7: =VLOOKUP(A7,'Hospitalisation Details'!A:B,2,0) -> 1962 | K7: =VLOOKUP(A7,'Hospitalisation Details'!A:C,3,0) -> Aug | L7: =VLOOKUP(A7,'Hospitalisation Details'!A:D,4,0) -> 4 | M7: =VLOOKUP(A7,'Hospitalisation Details'!A:E,5,0) -> 0 | N7: =VLOOKUP(A7,'Hospitalisation Details'!A:F,6,0) -> 52590.83 | O7: =VLOOKUP(A7,'Hospitalisation Details'!A:G,7,0) -> tier - 1 | P7: =VLOOKUP(A7,'Hospitalisation Details'!A:I,8,0) -> tier - 3 | Q7: =VLOOKUP(A7,'Hospitalisation Details'!A:I,9,0) -> R1011
A8: Id7 | B8: =VLOOKUP(A8,'Customer Names'!A:B,2,0) -> Macpherson, Mr. Scott | C8: =VLOOKUP(A8,'Medical Examinations'!A:H,2,0) -> 36.4 | D8: =VLOOKUP(A8,'Medical Examinations'!A:C,3,0) -> 6.07 | E8: =VLOOKUP(A8,'Medical Examinations'!A:E,4) -> No | F8: =VLOOKUP(A8,'Medical Examinations'!A:E,5) -> No | G8: =VLOOKUP(A8,'Medical Examinations'!A:F,6,0) -> No | H8: =VLOOKUP(A8,'Medical Examinations'!A:G,7) -> 1 | I8: =VLOOKUP(A8,'Medical Examinations'!A:H,8,0) -> yes | J8: =VLOOKUP(A8,'Hospitalisation Details'!A:B,2,0) -> 1994 | K8: =VLOOKUP(A8,'Hospitalisation Details'!A:C,3,0) -> Oct | L8: =VLOOKUP(A8,'Hospitalisation Details'!A:D,4,0) -> 27 | M8: =VLOOKUP(A8,'Hospitalisation Details'!A:E,5,0) -> 1 | N8: =VLOOKUP(A8,'Hospitalisation Details'!A:F,6,0) -> 51194.56 | O8: =VLOOKUP(A8,'Hospitalisation Details'!A:G,7,0) -> tier - 1 | P8: =VLOOKUP(A8,'Hospitalisation Details'!A:I,8,0) -> tier - 3 | Q8: =VLOOKUP(A8,'Hospitalisation Details'!A:I,9,0) -> R1011
A9: Id8 | B9: =VLOOKUP(A9,'Customer Names'!A:B,2,0) -> Hallman, Mr. Stephen | C9: =VLOOKUP(A9,'Medical Examinations'!A:H,2,0) -> 36.96 | D9: =VLOOKUP(A9,'Medical Examinations'!A:C,3,0) -> 7.93 | E9: =VLOOKUP(A9,'Medical Examinations'!A:E,4) -> No | F9: =VLOOKUP(A9,'Medical Examinations'!A:E,5) -> No | G9: =VLOOKUP(A9,'Medical Examinations'!A:F,6,0) -> No | H9: =VLOOKUP(A9,'Medical Examinations'!A:G,7) -> 1 | I9: =VLOOKUP(A9,'Medical Examinations'!A:H,8,0) -> yes | J9: =VLOOKUP(A9,'Hospitalisation Details'!A:B,2,0) -> 1958 | K9: =VLOOKUP(A9,'Hospitalisation Details'!A:C,3,0) -> Jun | L9: =VLOOKUP(A9,'Hospitalisation Details'!A:D,4,0) -> 27 | M9: =VLOOKUP(A9,'Hospitalisation Details'!A:E,5,0) -> 2 | N9: =VLOOKUP(A9,'Hospitalisation Details'!A:F,6,0) -> 49577.66 | O9: =VLOOKUP(A9,'Hospitalisation Details'!A:G,7,0) -> tier - 2 | P9: =VLOOKUP(A9,'Hospitalisation Details'!A:I,8,0) -> tier - 2 | Q9: =VLOOKUP(A9,'Hospitalisation Details'!A:I,9,0) -> R1013
A10: Id9 | B10: =VLOOKUP(A10,'Customer Names'!A:B,2,0) -> Moran, Mr. Patrick R. | C10: =VLOOKUP(A10,'Medical Examinations'!A:H,2,0) -> 41.14 | D10: =VLOOKUP(A10,'Medical Examinations'!A:C,3,0) -> 9.58 | E10: =VLOOKUP(A10,'Medical Examinations'!A:E,4) -> No | F10: =VLOOKUP(A10,'Medical Examinations'!A:E,5) -> No | G10: =VLOOKUP(A10,'Medical Examinations'!A:F,6,0) -> Yes | H10: =VLOOKUP(A10,'Medical Examinations'!A:G,7) -> 1 | I10: =VLOOKUP(A10,'Medical Examinations'!A:H,8,0) -> yes | J10: =VLOOKUP(A10,'Hospitalisation Details'!A:B,2,0) -> 1963 | K10: =VLOOKUP(A10,'Hospitalisation Details'!A:C,3,0) -> Sep | L10: =VLOOKUP(A10,'Hospitalisation Details'!A:D,4,0) -> 4 | M10: =VLOOKUP(A10,'Hospitalisation Details'!A:E,5,0) -> 1 | N10: =VLOOKUP(A10,'Hospitalisation Details'!A:F,6,0) -> 48970.25 | O10: =VLOOKUP(A10,'Hospitalisation Details'!A:G,7,0) -> tier - 1 | P10: =VLOOKUP(A10,'Hospitalisation Details'!A:I,8,0) -> tier - 2 | Q10: =VLOOKUP(A10,'Hospitalisation Details'!A:I,9,0) -> R1013
A11: Id10 | B11: =VLOOKUP(A11,'Customer Names'!A:B,2,0) -> Benner, Ms. Brooke N. | C11: =VLOOKUP(A11,'Medical Examinations'!A:H,2,0) -> 38.06 | D11: =VLOOKUP(A11,'Medical Examinations'!A:C,3,0) -> 10.79 | E11: =VLOOKUP(A11,'Medical Examinations'!A:E,4) -> No | F11: =VLOOKUP(A11,'Medical Examinations'!A:E,5) -> No | G11: =VLOOKUP(A11,'Medical Examinations'!A:F,6,0) -> No | H11: =VLOOKUP(A11,'Medical Examinations'!A:G,7) -> No major surgery | I11: =VLOOKUP(A11,'Medical Examinations'!A:H,8,0) -> yes | J11: =VLOOKUP(A11,'Hospitalisation Details'!A:B,2,0) -> 1978 | K11: =VLOOKUP(A11,'Hospitalisation Details'!A:C,3,0) -> Dec | L11: =VLOOKUP(A11,'Hospitalisation Details'!A:D,4,0) -> 29 | M11: =VLOOKUP(A11,'Hospitalisation Details'!A:E,5,0) -> 0 | N11: =VLOOKUP(A11,'Hospitalisation Details'!A:F,6,0) -> 48885.14 | O11: =VLOOKUP(A11,'Hospitalisation Details'!A:G,7,0) -> tier - 1 | P11: =VLOOKUP(A11,'Hospitalisation Details'!A:I,8,0) -> tier - 2 | Q11: =VLOOKUP(A11,'Hospitalisation Details'!A:I,9,0) -> R1013
A12: Id11 | B12: =VLOOKUP(A12,'Customer Names'!A:B,2,0) -> Fierro Vargas, Ms. Paola Andrea | C12: =VLOOKUP(A12,'Medical Examinations'!A:H,2,0) -> 37.7 | D12: =VLOOKUP(A12,'Medical Examinations'!A:C,3,0) -> 5.96 | E12: =VLOOKUP(A12,'Medical Examinations'!A:E,4) -> yes | F12: =VLOOKUP(A12,'Medical Examinations'!A:E,5) -> No | G12: =VLOOKUP(A12,'Medical Examinations'!A:F,6,0) -> No | H12: =VLOOKUP(A12,'Medical Examinations'!A:G,7) -> 1 | I12: =VLOOKUP(A12,'Medical Examinations'!A:H,8,0) -> yes | J12: =VLOOKUP(A12,'Hospitalisation Details'!A:B,2,0) -> 1959 | K12: =VLOOKUP(A12,'Hospitalisation Details'!A:C,3,0) -> Jul | L12: =VLOOKUP(A12,'Hospitalisation Details'!A:D,4,0) -> 22 | M12: =VLOOKUP(A12,'Hospitalisation Details'!A:E,5,0) -> 0 | N12: =VLOOKUP(A12,'Hospitalisation Details'!A:F,6,0) -> 48824.45 | O12: =VLOOKUP(A12,'Hospitalisation Details'!A:G,7,0) -> tier - 2 | P12: =VLOOKUP(A12,'Hospitalisation Details'!A:I,8,0) -> tier - 1 | Q12: =VLOOKUP(A12,'Hospitalisation Details'!A:I,9,0) -> R1011
A13: Id12 | B13: =VLOOKUP(A13,'Customer Names'!A:B,2,0) -> Franz, Mr. David | C13: =VLOOKUP(A13,'Medical Examinations'!A:H,2,0) -> 42.13 | D13: =VLOOKUP(A13,'Medical Examinations'!A:C,3,0) -> 11.9 | E13: =VLOOKUP(A13,'Medical Examinations'!A:E,4) -> No | F13: =VLOOKUP(A13,'Medical Examinations'!A:E,5) -> No | G13: =VLOOKUP(A13,'Medical Examinations'!A:F,6,0) -> No | H13: =VLOOKUP(A13,'Medical Examinations'!A:G,7) -> No major surgery | I13: =VLOOKUP(A13,'Medical Examinations'!A:H,8,0) -> yes | J13: =VLOOKUP(A13,'Hospitalisation Details'!A:B,2,0) -> 1965 | K13: =VLOOKUP(A13,'Hospitalisation Details'!A:C,3,0) -> Oct | L13: =VLOOKUP(A13,'Hospitalisation Details'!A:D,4,0) -> 27 | M13: =VLOOKUP(A13,'Hospitalisation Details'!A:E,5,0) -> 1 | N13: =VLOOKUP(A13,'Hospitalisation Details'!A:F,6,0) -> 48675.52 | O13: =VLOOKUP(A13,'Hospitalisation Details'!A:G,7,0) -> tier - 1 | P13: =VLOOKUP(A13,'Hospitalisation Details'!A:I,8,0) -> tier - 2 | Q13: =VLOOKUP(A13,'Hospitalisation Details'!A:I,9,0) -> R1013
A14: Id13 | B14: =VLOOKUP(A14,'Customer Names'!A:B,2,0) -> Foster, Mr. Wade | C14: =VLOOKUP(A14,'Medical Examinations'!A:H,2,0) -> 40.92 | D14: =VLOOKUP(A14,'Medical Examinations'!A:C,3,0) -> 8.41 | E14: =VLOOKUP(A14,'Medical Examinations'!A:E,4) -> yes | F14: =VLOOKUP(A14,'Medical Examinations'!A:E,5) -> No | G14: =VLOOKUP(A14,'Medical Examinations'!A:F,6,0) -> No | H14: =VLOOKUP(A14,'Medical Examinations'!A:G,7) -> 2 | I14: =VLOOKUP(A14,'Medical Examinations'!A:H,8,0) -> yes | J14: =VLOOKUP(A14,'Hospitalisation Details'!A:B,2,0) -> 1962 | K14: =VLOOKUP(A14,'Hospitalisation Details'!A:C,3,0) -> Oct | L14: =VLOOKUP(A14,'Hospitalisation Details'!A:D,4,0) -> 11 | M14: =VLOOKUP(A14,'Hospitalisation Details'!A:E,5,0) -> 0 | N14: =VLOOKUP(A14,'Hospitalisation Details'!A:F,6,0) -> 48673.56 | O14: =VLOOKUP(A14,'Hospitalisation Details'!A:G,7,0) -> tier - 1 | P14: =VLOOKUP(A14,'Hospitalisation Details'!A:I,8,0) -> tier - 2 | Q14: =VLOOKUP(A14,'Hospitalisation Details'!A:I,9,0) -> R1013
A15: Id14 | B15: =VLOOKUP(A15,'Customer Names'!A:B,2,0) -> Tenorio, Mr. Franklin | C15: =VLOOKUP(A15,'Medical Examinations'!A:H,2,0) -> 40.565 | D15: =VLOOKUP(A15,'Medical Examinations'!A:C,3,0) -> 7.02 | E15: =VLOOKUP(A15,'Medical Examinations'!A:E,4) -> No | F15: =VLOOKUP(A15,'Medical Examinations'!A:E,5) -> No | G15: =VLOOKUP(A15,'Medical Examinations'!A:F,6,0) -> No | H15: =VLOOKUP(A15,'Medical Examinations'!A:G,7) -> No major surgery | I15: =VLOOKUP(A15,'Medical Examinations'!A:H,8,0) -> yes | J15: =VLOOKUP(A15,'Hospitalisation Details'!A:B,2,0) -> 1968 | K15: =VLOOKUP(A15,'Hospitalisation Details'!A:C,3,0) -> Dec | L15: =VLOOKUP(A15,'Hospitalisation Details'!A:D,4,0) -> 1 | M15: =VLOOKUP(A15,'Hospitalisation Details'!A:E,5,0) -> 3 | N15: =VLOOKUP(A15,'Hospitalisation Details'!A:F,6,0) -> 48549.18 | O15: =VLOOKUP(A15,'Hospitalisation Details'!A:G,7,0) -> tier - 1 | P15: =VLOOKUP(A15,'Hospitalisation Details'!A:I,8,0) -> tier - 3 | Q15: =VLOOKUP(A15,'Hospitalisation Details'!A:I,9,0) -> R1016
A16: Id15 | B16: =VLOOKUP(A16,'Customer Names'!A:B,2,0) -> Rios, Ms. Leilani M. | C16: =VLOOKUP(A16,'Medical Examinations'!A:H,2,0) -> 36.385 | D16: =VLOOKUP(A16,'Medical Examinations'!A:C,3,0) -> 7.59 | E16: =VLOOKUP(A16,'Medical Examinations'!A:E,4) -> No | F16: =VLOOKUP(A16,'Medical Examinations'!A:E,5) -> No | G16: =VLOOKUP(A16,'Medical Examinations'!A:F,6,0) -> No | H16: =VLOOKUP(A16,'Medical Examinations'!A:G,7) -> No major surgery | I16: =VLOOKUP(A16,'Medical Examinations'!A:H,8,0) -> yes | J16: =VLOOKUP(A16,'Hospitalisation Details'!A:B,2,0) -> 1961 | K16: =VLOOKUP(A16,'Hospitalisation Details'!A:C,3,0) -> Dec | L16: =VLOOKUP(A16,'Hospitalisation Details'!A:D,4,0) -> 21 | M16: =VLOOKUP(A16,'Hospitalisation Details'!A:E,5,0) -> 1 | N16: =VLOOKUP(A16,'Hospitalisation Details'!A:F,6,0) -> 48517.56 | O16: =VLOOKUP(A16,'Hospitalisation Details'!A:G,7,0) -> tier - 1 | P16: =VLOOKUP(A16,'Hospitalisation Details'!A:I,8,0) -> tier - 3 | Q16: =VLOOKUP(A16,'Hospitalisation Details'!A:I,9,0) -> R1024
... A2318: Id2317 | B2318: =VLOOKUP(A2318,'Customer Names'!A:B,2,0) -> Murakami, Mr. Koji | C2318: =VLOOKUP(A2318,'Medical Examinations'!A:H,2,0) -> 20.47 | D2318: =VLOOKUP(A2318,'Medical Examinations'!A:C,3,0) -> 5.81 | E2318: =VLOOKUP(A2318,'Medical Examinations'!A:E,4) -> yes | F2318: =VLOOKUP(A2318,'Medical Examinations'!A:E,5) -> No | G2318: =VLOOKUP(A2318,'Medical Examinations'!A:F,6,0) -> No | H2318: =VLOOKUP(A2318,'Medical Examinations'!A:G,7) -> 1 | I2318: =VLOOKUP(A2318,'Medical Examinations'!A:H,8,0) -> No | J2318: =VLOOKUP(A2318,'Hospitalisation Details'!A:B,2,0) -> 1995 | K2318: =VLOOKUP(A2318,'Hospitalisation Details'!A:C,3,0) -> Dec | L2318: =VLOOKUP(A2318,'Hospitalisation Details'!A:D,4,0) -> 7 | M2318: =VLOOKUP(A2318,'Hospitalisation Details'!A:E,5,0) -> 0 | N2318: =VLOOKUP(A2318,'Hospitalisation Details'!A:F,6,0) -> 773.54 | O2318: =VLOOKUP(A2318,'Hospitalisation Details'!A:G,7,0) -> tier - 3 | P2318: =VLOOKUP(A2318,'Hospitalisation Details'!A:I,8,0) -> tier - 2 | Q2318: =VLOOKUP(A2318,'Hospitalisation Details'!A:I,9,0) -> R1013
A2319: Id2318 | B2319: =VLOOKUP(A2319,'Customer Names'!A:B,2,0) -> Gagnon, Ms. Candice M | C2319: =VLOOKUP(A2319,'Medical Examinations'!A:H,2,0) -> 18.82 | D2319: =VLOOKUP(A2319,'Medical Examinations'!A:C,3,0) -> 5.51 | E2319: =VLOOKUP(A2319,'Medical Examinations'!A:E,4) -> yes | F2319: =VLOOKUP(A2319,'Medical Examinations'!A:E,5) -> No | G2319: =VLOOKUP(A2319,'Medical Examinations'!A:F,6,0) -> No | H2319: =VLOOKUP(A2319,'Medical Examinations'!A:G,7) -> No major surgery | I2319: =VLOOKUP(A2319,'Medical Examinations'!A:H,8,0) -> No | J2319: =VLOOKUP(A2319,'Hospitalisation Details'!A:B,2,0) -> 1996 | K2319: Sep | L2319: =VLOOKUP(A2319,'Hospitalisation Details'!A:D,4,0) -> 18 | M2319: =VLOOKUP(A2319,'Hospitalisation Details'!A:E,5,0) -> 0 | N2319: =VLOOKUP(A2319,'Hospitalisation Details'!A:F,6,0) -> 770.38 | O2319: =VLOOKUP(A2319,'Hospitalisation Details'!A:G,7,0) -> tier - 3 | P2319: =VLOOKUP(A2319,'Hospitalisation Details'!A:I,8,0) -> tier - 2 | Q2319: =VLOOKUP(A2319,'Hospitalisation Details'!A:I,9,0) -> R1012
A2320: Id2319 | B2320: =VLOOKUP(A2320,'Customer Names'!A:B,2,0) -> Petermann, Mr. Theodore A. | C2320: =VLOOKUP(A2320,'Medical Examinations'!A:H,2,0) -> 17.08 | D2320: =VLOOKUP(A2320,'Medical Examinations'!A:C,3,0) -> 5.73 | E2320: =VLOOKUP(A2320,'Medical Examinations'!A:E,4) -> No | F2320: =VLOOKUP(A2320,'Medical Examinations'!A:E,5) -> No | G2320: =VLOOKUP(A2320,'Medical Examinations'!A:F,6,0) -> Yes | H2320: =VLOOKUP(A2320,'Medical Examinations'!A:G,7) -> 1 | I2320: =VLOOKUP(A2320,'Medical Examinations'!A:H,8,0) -> No | J2320: =VLOOKUP(A2320,'Hospitalisation Details'!A:B,2,0) -> 1993 | K2320: =VLOOKUP(A2320,'Hospitalisation Details'!A:C,3,0) -> Jun | L2320: =VLOOKUP(A2320,'Hospitalisation Details'!A:D,4,0) -> 28 | M2320: =VLOOKUP(A2320,'Hospitalisation Details'!A:E,5,0) -> 0 | N2320: =VLOOKUP(A2320,'Hospitalisation Details'!A:F,6,0) -> 770 | O2320: =VLOOKUP(A2320,'Hospitalisation Details'!A:G,7,0) -> tier - 3 | P2320: =VLOOKUP(A2320,'Hospitalisation Details'!A:I,8,0) -> tier - 3 | Q2320: =VLOOKUP(A2320,'Hospitalisation Details'!A:I,9,0) -> R1013
A2321: Id2320 | B2321: =VLOOKUP(A2321,'Customer Names'!A:B,2,0) -> Graves - Rostro, Ms. Lindy | C2321: =VLOOKUP(A2321,'Medical Examinations'!A:H,2,0) -> 19.21 | D2321: =VLOOKUP(A2321,'Medical Examinations'!A:C,3,0) -> 5.53 | E2321: =VLOOKUP(A2321,'Medical Examinations'!A:E,4) -> yes | F2321: =VLOOKUP(A2321,'Medical Examinations'!A:E,5) -> No | G2321: =VLOOKUP(A2321,'Medical Examinations'!A:F,6,0) -> No | H2321: =VLOOKUP(A2321,'Medical Examinations'!A:G,7) -> No major surgery | I2321: =VLOOKUP(A2321,'Medical Examinations'!A:H,8,0) -> No | J2321: =VLOOKUP(A2321,'Hospitalisation Details'!A:B,2,0) -> 1996 | K2321: =VLOOKUP(A2321,'Hospitalisation Details'!A:C,3,0) -> Oct | L2321: =VLOOKUP(A2321,'Hospitalisation Details'!A:D,4,0) -> 22 | M2321: =VLOOKUP(A2321,'Hospitalisation Details'!A:E,5,0) -> 0 | N2321: =VLOOKUP(A2321,'Hospitalisation Details'!A:F,6,0) -> 760 | O2321: =VLOOKUP(A2321,'Hospitalisation Details'!A:G,7,0) -> tier - 3 | P2321: =VLOOKUP(A2321,'Hospitalisation Details'!A:I,8,0) -> tier - 3 | Q2321: =VLOOKUP(A2321,'Hospitalisation Details'!A:I,9,0) -> R1013
A2322: Id2321 | B2322: =VLOOKUP(A2322,'Customer Names'!A:B,2,0) -> Danielson, Mr. Thomas | C2322: =VLOOKUP(A2322,'Medical Examinations'!A:H,2,0) -> 17.86 | D2322: =VLOOKUP(A2322,'Medical Examinations'!A:C,3,0) -> 5.43 | E2322: =VLOOKUP(A2322,'Medical Examinations'!A:E,4) -> No | F2322: =VLOOKUP(A2322,'Medical Examinations'!A:E,5) -> No | G2322: =VLOOKUP(A2322,'Medical Examinations'!A:F,6,0) -> Yes | H2322: =VLOOKUP(A2322,'Medical Examinations'!A:G,7) -> 1 | I2322: =VLOOKUP(A2322,'Medical Examinations'!A:H,8,0) -> No | J2322: =VLOOKUP(A2322,'Hospitalisation Details'!A:B,2,0) -> 1993 | K2322: =VLOOKUP(A2322,'Hospitalisation Details'!A:C,3,0) -> Aug | L2322: =VLOOKUP(A2322,'Hospitalisation Details'!A:D,4,0) -> 9 | M2322: =VLOOKUP(A2322,'Hospitalisation Details'!A:E,5,0) -> 0 | N2322: =VLOOKUP(A2322,'Hospitalisation Details'!A:F,6,0) -> 760 | O2322: =VLOOKUP(A2322,'Hospitalisation Details'!A:G,7,0) -> tier - 3 | P2322: =VLOOKUP(A2322,'Hospitalisation Details'!A:I,8,0) -> tier - 1 | Q2322: =VLOOKUP(A2322,'Hospitalisation Details'!A:I,9,0) -> R1013
A2323: Id2322 | B2323: =VLOOKUP(A2323,'Customer Names'!A:B,2,0) -> Street, Ms. Holly | C2323: =VLOOKUP(A2323,'Medical Examinations'!A:H,2,0) -> 21.38 | D2323: =VLOOKUP(A2323,'Medical Examinations'!A:C,3,0) -> 8.01 | E2323: =VLOOKUP(A2323,'Medical Examinations'!A:E,4) -> No | F2323: =VLOOKUP(A2323,'Medical Examinations'!A:E,5) -> No | G2323: =VLOOKUP(A2323,'Medical Examinations'!A:F,6,0) -> No | H2323: =VLOOKUP(A2323,'Medical Examinations'!A:G,7) -> No major surgery | I2323: =VLOOKUP(A2323,'Medical Examinations'!A:H,8,0) -> No | J2323: =VLOOKUP(A2323,'Hospitalisation Details'!A:B,2,0) -> 2002 | K2323: Sep | L2323: =VLOOKUP(A2323,'Hospitalisation Details'!A:D,4,0) -> 19 | M2323: =VLOOKUP(A2323,'Hospitalisation Details'!A:E,5,0) -> 0 | N2323: =VLOOKUP(A2323,'Hospitalisation Details'!A:F,6,0) -> 750 | O2323: =VLOOKUP(A2323,'Hospitalisation Details'!A:G,7,0) -> tier - 3 | P2323: =VLOOKUP(A2323,'Hospitalisation Details'!A:I,8,0) -> tier - 1 | Q2323: =VLOOKUP(A2323,'Hospitalisation Details'!A:I,9,0) -> R1012
